Workbook

Sheet PROJE_OZETI
A1: KARAKTER PROJESİ — YÖNETİM VE DEVAM DOSYASI
A2: Sürüm: V1 / 56 kart • Son kontrol: 23.09.2026 • Bu sayfa dosyanın başlangıç noktasıdır.
A4: Toplam Karakter | B4: =COUNTA(Tum_Karakterler_311!A2:A312) -> 311 | C4: V1 Kart | D4: =COUNTA(V1_Kadro_56!A5:A60) -> 56 | E4: Hazır Görsel | F4: =COUNTIF(V1_Kadro_56!F5:F60,"Hazır") -> 56 | G4: Üretilecek Görsel | H4: =COUNTIF(V1_Kadro_56!F5:F60,"Üretilecek") -> 0
A6: DOSYAYI NASIL KULLANMALIYIZ?
A7: 1 | B7: Ana veri kaynağı | D7: Tum_Karakterler_311 tüm 311 karakter için tek doğruluk kaynağıdır. Karakter bilgilerini önce burada güncelleyin.
A8: 2 | B8: V1 kararı | D8: V1_Kadro_56 yalnızca onaylı 56 kartı içerir. Kadro değişirse denge ve üretim listelerini yeniden kontrol edin.
A9: 3 | B9: Sınıf sekmeleri | D9: Destek, Ninja, Tank, Büyücü ve Savaşçı sekmeleri aynadır. Ana sayfadaki değişiklikleri aynı ID satırına senkronlayın.
A10: 4 | B10: Görsel üretimi | D10: V1_Uretilecek_14 lansman öncesi açık görsel işleridir. Takip Durumu sütununu ekip güncelleyebilir.
A11: 5 | B11: Teknik geçmiş | D11: Gizli teknik sekmeler karar geçmişini korur; günlük kullanım için gerekli değildir. Gerektiğinde gösterilebilir.
A12: 6 | B12: Bilgi | D12: Her karakterin %2 kritik vuruş şansı vardır
A13: V1 ONAY ÖZETİ
A14: Nadirlik planı | B14: 20 Yaygın • 16 Nadir • 10 Ender • 5 Efsanevi • 5 Multi | G14: Onaylı
A15: Sınıf planı | B15: Destek 11 • Ninja 11 • Tank 11 • Büyücü 11 • Savaşçı 12 | G15: Onaylı
A16: Irk sözlüğü | B16: 14 ana ırk; element, meslek ve unvanlar ana ırk değildir. | G16: Onaylı
A17: Görsel durumu | B17: 42 hazır • 14 üretilecek • V1’de hafif düzenleme veya çakışmalı görsel yok. | G17: 14 açık iş
A18: Hikâye limiti | B18: 311 hikâye dolu; ID 192 düzeltildi ve 130 karaktere indirildi. | G18: Uygun
A20: BİLİNEN NOTLAR VE GÜVENLİ DEVAM KURALLARI
A21: • Kara_Pence adı iki ayrı karakterde bulunur (ID 104 ve ID 264). Otomatik birleştirmeyin; ID anahtardır.
A22: • ID 135 için tam görsel yenileme kararı vardır; V1 kadrosunda olmadığı için lansman engeli değildir.
A23: • Yeni ırk eklemeyin. Ana ırk değerleri yalnızca Irk_Sozlugu sayfasındaki 14 değerden biri olmalıdır.
A24: • Bu dosyada eski 54 kartlık V1 planı kaldırılmıştır; yalnızca V1_Kadro_56 günceldir.
A26: HIZLI SAYFA REHBERİ
A27: V1_Kadro_56 | D27: Onaylı 56 kart | E27: V1_Uretilecek_14 | H27: Görsel backlog
A28: V1_Sinif_Nadirlik | D28: Denge matrisi | E28: Gorsel_Durum_311 | H28: Tüm görsel denetimi
A29: Irk_Sozlugu | D29: 14 ırk kuralı | E29: Tum_Karakterler_311 | H29: 311 ana kayıt
A30: QA_KONTROL | D30: Canlı kalite kontrolleri | E30: KAYNAK_VE_KURALLAR | H30: Ekip çalışma sözlüğü

Sheet V1_Kadro_56
A1: V1 KADROSU — 56 KART
A2: Onaylı ve dengeli lansman kadrosu • Filtreleri kullanın • Kadro kararı değişirse denge sayfalarını kontrol edin
A4: ID | B4: Karakter | C4: Sınıf | D4: Nadirlik | E4: Irk | F4: Görsel Durumu | G4: Görsel Sayısı | H4: Görsel Dosyaları | I4: Karar Güveni | J4: V1 Notu
A5: 188 | B5: Ates_Ciragi | C5: Büyücü | D5: Yaygın | E5: İnsan | F5: Hazır | G5: 3 | H5: ATES CIRAGI.jpg | ATES_CIRAGI_erkek.jpg | ATES_CIRAGI_KIZ.jpg | I5: Onaylı | J5: Mevcut görselle V1’e hazır.
A6: 189 | B6: Buz_Ogrencisi | C6: Büyücü | D6: Yaygın | E6: İnsan | F6: Hazır | G6: 2 | H6: BUZ OGRENCISI.jpg | BUZ_OGRENCISI_KIZ.jpg | I6: Onaylı | J6: Mevcut görselle V1’e hazır.
A7: 192 | B7: Kita_Buyucusu | C7: Büyücü | D7: Yaygın | E7: İnsan | F7: Hazır | G7: 1 | H7: Kita_Buyucusu.jpg | I7: Onaylı | J7: Mevcut görselle V1’e hazır.
A8: 217 | B8: Galaktik_Bilgisi | C8: Büyücü | D8: Yaygın | E8: Astral | F8: Hazır | G8: 1 | H8: Galaktik_Bilgisi.png | I8: Onaylı | J8: Mevcut görselle V1’e hazır.
A9: 1 | B9: CIRAK_SIFACI | C9: Destek | D9: Yaygın | E9: İnsan | F9: Hazır | G9: 1 | H9: CIRAK SIFACI.png | I9: Onaylı | J9: Mevcut görselle V1’e hazır.
A10: 2 | B10: RUH_BEKCISI | C10: Destek | D10: Yaygın | E10: İnsan | F10: Hazır | G10: 1 | H10: RUH BEKCISI.png | I10: Onaylı | J10: Mevcut görselle V1’e hazır.
A11: 8 | B11: Sonsuz_Sifaci | C11: Destek | D11: Yaygın | E11: Ölümsüz | F11: Hazır | G11: 1 | H11: Sonsuz Sifaci.png | I11: Onaylı | J11: Mevcut görselle V1’e hazır.
A12: 17 | B12: Evren_Sifacisi | C12: Destek | D12: Yaygın | E12: Astral | F12: Hazır | G12: 1 | H12: Evren Sifacisi.png | I12: Onaylı | J12: Mevcut görselle V1’e hazır.
A13: 64 | B13: Golge_Cirag | C13: Ninja | D13: Yaygın | E13: Gölge | F13: Hazır | G13: 1 | H13: Gölge Çırağı - Gölge.jpg | I13: Onaylı | J13: Mevcut görselle V1’e hazır.
A14: 67 | B14: Golgelerin_Ustasi | C14: Ninja | D14: Yaygın | E14: Gölge | F14: Hazır | G14: 1 | H14: Gölgelerin Ustası - Gölge.jpg | I14: Onaylı | J14: Mevcut görselle V1’e hazır.
A15: 70 | B15: Nightmare_Karabasan | C15: Ninja | D15: Yaygın | E15: Gölge | F15: Hazır | G15: 1 | H15: Karabasan - Gölge.jpg | I15: Onaylı | J15: Mevcut görselle V1’e hazır.
A16: 71 | B16: Gizli_Yikici | C16: Ninja | D16: Yaygın | E16: Cüce | F16: Hazır | G16: 1 | H16: Gizli Yıkıcı - Cüce.jpg | I16: Onaylı | J16: Mevcut görselle V1’e hazır.
... A60: 311 | B60: Kaos_Sampiyonu | C60: Savaşçı | D60: Multi | E60: Astral | F60: Hazır | G60: 0 | H60: — | I60: Onaylı | J60: Yeni görsel V1 öncesi üretilmeli.

Sheet V1_Uretilecek_14
A1: V1 GÖRSEL ÜRETİM LİSTESİ — 14
A2: Bu listedeki işler V1 lansmanının tek açık görsel üretim backlog’udur.
A4: Sıra | B4: ID | C4: Karakter | D4: Sınıf | E4: Nadirlik | F4: Irk | G4: İş | H4: V1 Engeli | I4: Takip Durumu
A5: 1 | B5: 282 | C5: ALEV_KILICI | D5: Savaşçı | E5: Nadir | F5: Canavar | G5: Yeni görsel üret | H5: Evet | I5: Bekliyor
A6: 2 | B6: 283 | C6: FIRTINA_DOVUSCUSU | D6: Savaşçı | E6: Nadir | F6: Canavar | G6: Yeni görsel üret | H6: Evet | I6: Bekliyor
A7: 3 | B7: 285 | C7: Simsek_Dovuscusu | D7: Savaşçı | E7: Nadir | F7: Mutant | G7: Yeni görsel üret | H7: Evet | I7: Bekliyor
A8: 4 | B8: 286 | C8: Buyuk_Celik_Lordu | D8: Savaşçı | E8: Nadir | F8: Dev | G8: Yeni görsel üret | H8: Evet | I8: Bekliyor
A9: 5 | B9: 112 | C9: RUH_BICICI | D9: Ninja | E9: Ender | F9: Ölümsüz | G9: Yeni görsel üret | H9: Evet | I9: Bekliyor
A10: 6 | B10: 117 | C10: Sonsuz_Pence | D10: Ninja | E10: Ender | F10: Böceksırt | G10: Yeni görsel üret | H10: Evet | I10: Bekliyor
A11: 7 | B11: 298 | C11: KARA_SOVALYE | D11: Savaşçı | E11: Ender | F11: Dev | G11: Yeni görsel üret | H11: Evet | I11: Bekliyor
A12: 8 | B12: 302 | C12: Firtina_Aslani | D12: Savaşçı | E12: Ender | F12: Canavar | G12: Yeni görsel üret | H12: Evet | I12: Bekliyor
A13: 9 | B13: 57 | C13: KADIM_SIFACI | D13: Destek | E13: Efsanevi | F13: Mutant | G13: Yeni görsel üret | H13: Evet | I13: Bekliyor
A14: 10 | B14: 120 | C14: GOLGE_LORDU | D14: Ninja | E14: Efsanevi | F14: Gölge | G14: Yeni görsel üret | H14: Evet | I14: Bekliyor
A15: 11 | B15: 306 | C15: ZAFER_MELEGI | D15: Savaşçı | E15: Efsanevi | F15: Melek | G15: Yeni görsel üret | H15: Evet | I15: Bekliyor
A16: 12 | B16: 61 | C16: IYILESTIRME_TANRISI | D16: Destek | E16: Multi | F16: Tanrısal | G16: Yeni görsel üret | H16: Evet | I16: Bekliyor
... A18: 14 | B18: 311 | C18: KAOS_SAMPIYONU | D18: Savaşçı | E18: Multi | F18: Astral | G18: Yeni görsel üret | H18: Evet | I18: Bekliyor

Sheet V1_Sinif_Nadirlik
A1: V1 SINIF × NADİRLİK DENGESİ
A2: Matematiksel olarak mümkün olan en yakın denge: 56 kart / 5 sınıf.
A4: Sınıf | B4: Yaygın | C4: Nadir | D4: Ender | E4: Efsanevi | F4: Multi | G4: Toplam
A5: Destek | B5: =COUNTIFS(V1_Kadro_56!$C$5:$C$60,$A5,V1_Kadro_56!$D$5:$D$60,B$4) -> 4 | C5: =COUNTIFS(V1_Kadro_56!$C$5:$C$60,$A5,V1_Kadro_56!$D$5:$D$60,C$4) -> 3 | D5: =COUNTIFS(V1_Kadro_56!$C$5:$C$60,$A5,V1_Kadro_56!$D$5:$D$60,D$4) -> 2 | E5: =COUNTIFS(V1_Kadro_56!$C$5:$C$60,$A5,V1_Kadro_56!$D$5:$D$60,E$4) -> 1 | F5: =COUNTIFS(V1_Kadro_56!$C$5:$C$60,$A5,V1_Kadro_56!$D$5:$D$60,F$4) -> 1 | G5: =SUM(B5:F5) -> 11
A6: Ninja | B6: =COUNTIFS(V1_Kadro_56!$C$5:$C$60,$A6,V1_Kadro_56!$D$5:$D$60,B$4) -> 4 | C6: =COUNTIFS(V1_Kadro_56!$C$5:$C$60,$A6,V1_Kadro_56!$D$5:$D$60,C$4) -> 3 | D6: =COUNTIFS(V1_Kadro_56!$C$5:$C$60,$A6,V1_Kadro_56!$D$5:$D$60,D$4) -> 2 | E6: =COUNTIFS(V1_Kadro_56!$C$5:$C$60,$A6,V1_Kadro_56!$D$5:$D$60,E$4) -> 1 | F6: =COUNTIFS(V1_Kadro_56!$C$5:$C$60,$A6,V1_Kadro_56!$D$5:$D$60,F$4) -> 1 | G6: =SUM(B6:F6) -> 11
A7: Tank | B7: =COUNTIFS(V1_Kadro_56!$C$5:$C$60,$A7,V1_Kadro_56!$D$5:$D$60,B$4) -> 4 | C7: =COUNTIFS(V1_Kadro_56!$C$5:$C$60,$A7,V1_Kadro_56!$D$5:$D$60,C$4) -> 3 | D7: =COUNTIFS(V1_Kadro_56!$C$5:$C$60,$A7,V1_Kadro_56!$D$5:$D$60,D$4) -> 2 | E7: =COUNTIFS(V1_Kadro_56!$C$5:$C$60,$A7,V1_Kadro_56!$D$5:$D$60,E$4) -> 1 | F7: =COUNTIFS(V1_Kadro_56!$C$5:$C$60,$A7,V1_Kadro_56!$D$5:$D$60,F$4) -> 1 | G7: =SUM(B7:F7) -> 11
A8: Büyücü | B8: =COUNTIFS(V1_Kadro_56!$C$5:$C$60,$A8,V1_Kadro_56!$D$5:$D$60,B$4) -> 4 | C8: =COUNTIFS(V1_Kadro_56!$C$5:$C$60,$A8,V1_Kadro_56!$D$5:$D$60,C$4) -> 3 | D8: =COUNTIFS(V1_Kadro_56!$C$5:$C$60,$A8,V1_Kadro_56!$D$5:$D$60,D$4) -> 2 | E8: =COUNTIFS(V1_Kadro_56!$C$5:$C$60,$A8,V1_Kadro_56!$D$5:$D$60,E$4) -> 1 | F8: =COUNTIFS(V1_Kadro_56!$C$5:$C$60,$A8,V1_Kadro_56!$D$5:$D$60,F$4) -> 1 | G8: =SUM(B8:F8) -> 11
A9: Savaşçı | B9: =COUNTIFS(V1_Kadro_56!$C$5:$C$60,$A9,V1_Kadro_56!$D$5:$D$60,B$4) -> 4 | C9: =COUNTIFS(V1_Kadro_56!$C$5:$C$60,$A9,V1_Kadro_56!$D$5:$D$60,C$4) -> 4 | D9: =COUNTIFS(V1_Kadro_56!$C$5:$C$60,$A9,V1_Kadro_56!$D$5:$D$60,D$4) -> 2 | E9: =COUNTIFS(V1_Kadro_56!$C$5:$C$60,$A9,V1_Kadro_56!$D$5:$D$60,E$4) -> 1 | F9: =COUNTIFS(V1_Kadro_56!$C$5:$C$60,$A9,V1_Kadro_56!$D$5:$D$60,F$4) -> 1 | G9: =SUM(B9:F9) -> 12
A10: Toplam | B10: =SUM(B5:B9) -> 20 | C10: =SUM(C5:C9) -> 16 | D10: =SUM(D5:D9) -> 10 | E10: =SUM(E5:E9) -> 5 | F10: =SUM(F5:F9) -> 5 | G10: =SUM(G5:G9) -> 56
A12: ONAYLI KOTALAR
A13: Nadirlik | B13: Destek | C13: Ninja | D13: Tank | E13: Büyücü | F13: Savaşçı | G13: Toplam
A14: Yaygın | B14: 4 | C14: 4 | D14: 4 | E14: 4 | F14: 4 | G14: 20
A15: Nadir | B15: 3 | C15: 3 | D15: 3 | E15: 3 | F15: 4 | G15: 16
A16: Ender | B16: 2 | C16: 2 | D16: 2 | E16: 2 | F16: 2 | G16: 10
A17: Efsanevi | B17: 1 | C17: 1 | D17: 1 | E17: 1 | F17: 1 | G17: 5
A18: Multi | B18: 1 | C18: 1 | D18: 1 | E18: 1 | F18: 1 | G18: 5

Sheet V1_Sinif_Irk
A1: V1 SINIF × IRK DAĞILIMI
A2: V1 kadrosundaki ırksal çeşitliliğin sınıflara dağılımı.
A4: Sınıf | B4: İnsan | C4: Elf | D4: Cüce | E4: Ejdersoy | F4: Gölge | G4: Astral | H4: Mutant | I4: Tanrısal | J4: Sürüngensoy | K4: Böceksırt | L4: Canavar | M4: Ölümsüz | N4: Melek | O4: Dev | P4: Toplam
A5: Destek | B5: =COUNTIFS(V1_Kadro_56!$C$5:$C$60,$A5,V1_Kadro_56!$E$5:$E$60,B$4) -> 3 | C5: =COUNTIFS(V1_Kadro_56!$C$5:$C$60,$A5,V1_Kadro_56!$E$5:$E$60,C$4) -> 2 | D5: =COUNTIFS(V1_Kadro_56!$C$5:$C$60,$A5,V1_Kadro_56!$E$5:$E$60,D$4) -> 0 | E5: =COUNTIFS(V1_Kadro_56!$C$5:$C$60,$A5,V1_Kadro_56!$E$5:$E$60,E$4) -> 0 | F5: =COUNTIFS(V1_Kadro_56!$C$5:$C$60,$A5,V1_Kadro_56!$E$5:$E$60,F$4) -> 0 | G5: =COUNTIFS(V1_Kadro_56!$C$5:$C$60,$A5,V1_Kadro_56!$E$5:$E$60,G$4) -> 2 | H5: =COUNTIFS(V1_Kadro_56!$C$5:$C$60,$A5,V1_Kadro_56!$E$5:$E$60,H$4) -> 1 | I5: =COUNTIFS(V1_Kadro_56!$C$5:$C$60,$A5,V1_Kadro_56!$E$5:$E$60,I$4) -> 1 | ... O5: =COUNTIFS(V1_Kadro_56!$C$5:$C$60,$A5,V1_Kadro_56!$E$5:$E$60,O$4) -> 0 | P5: =SUM(B5:O5) -> 11
A6: Ninja | B6: =COUNTIFS(V1_Kadro_56!$C$5:$C$60,$A6,V1_Kadro_56!$E$5:$E$60,B$4) -> 0 | C6: =COUNTIFS(V1_Kadro_56!$C$5:$C$60,$A6,V1_Kadro_56!$E$5:$E$60,C$4) -> 0 | D6: =COUNTIFS(V1_Kadro_56!$C$5:$C$60,$A6,V1_Kadro_56!$E$5:$E$60,D$4) -> 3 | E6: =COUNTIFS(V1_Kadro_56!$C$5:$C$60,$A6,V1_Kadro_56!$E$5:$E$60,E$4) -> 0 | F6: =COUNTIFS(V1_Kadro_56!$C$5:$C$60,$A6,V1_Kadro_56!$E$5:$E$60,F$4) -> 6 | G6: =COUNTIFS(V1_Kadro_56!$C$5:$C$60,$A6,V1_Kadro_56!$E$5:$E$60,G$4) -> 0 | H6: =COUNTIFS(V1_Kadro_56!$C$5:$C$60,$A6,V1_Kadro_56!$E$5:$E$60,H$4) -> 0 | I6: =COUNTIFS(V1_Kadro_56!$C$5:$C$60,$A6,V1_Kadro_56!$E$5:$E$60,I$4) -> 0 | ... O6: =COUNTIFS(V1_Kadro_56!$C$5:$C$60,$A6,V1_Kadro_56!$E$5:$E$60,O$4) -> 0 | P6: =SUM(B6:O6) -> 11
A7: Tank | B7: =COUNTIFS(V1_Kadro_56!$C$5:$C$60,$A7,V1_Kadro_56!$E$5:$E$60,B$4) -> 1 | C7: =COUNTIFS(V1_Kadro_56!$C$5:$C$60,$A7,V1_Kadro_56!$E$5:$E$60,C$4) -> 0 | D7: =COUNTIFS(V1_Kadro_56!$C$5:$C$60,$A7,V1_Kadro_56!$E$5:$E$60,D$4) -> 1 | E7: =COUNTIFS(V1_Kadro_56!$C$5:$C$60,$A7,V1_Kadro_56!$E$5:$E$60,E$4) -> 3 | F7: =COUNTIFS(V1_Kadro_56!$C$5:$C$60,$A7,V1_Kadro_56!$E$5:$E$60,F$4) -> 0 | G7: =COUNTIFS(V1_Kadro_56!$C$5:$C$60,$A7,V1_Kadro_56!$E$5:$E$60,G$4) -> 0 | H7: =COUNTIFS(V1_Kadro_56!$C$5:$C$60,$A7,V1_Kadro_56!$E$5:$E$60,H$4) -> 0 | I7: =COUNTIFS(V1_Kadro_56!$C$5:$C$60,$A7,V1_Kadro_56!$E$5:$E$60,I$4) -> 0 | ... O7: =COUNTIFS(V1_Kadro_56!$C$5:$C$60,$A7,V1_Kadro_56!$E$5:$E$60,O$4) -> 1 | P7: =SUM(B7:O7) -> 11
A8: Büyücü | B8: =COUNTIFS(V1_Kadro_56!$C$5:$C$60,$A8,V1_Kadro_56!$E$5:$E$60,B$4) -> 5 | C8: =COUNTIFS(V1_Kadro_56!$C$5:$C$60,$A8,V1_Kadro_56!$E$5:$E$60,C$4) -> 1 | D8: =COUNTIFS(V1_Kadro_56!$C$5:$C$60,$A8,V1_Kadro_56!$E$5:$E$60,D$4) -> 0 | E8: =COUNTIFS(V1_Kadro_56!$C$5:$C$60,$A8,V1_Kadro_56!$E$5:$E$60,E$4) -> 0 | F8: =COUNTIFS(V1_Kadro_56!$C$5:$C$60,$A8,V1_Kadro_56!$E$5:$E$60,F$4) -> 0 | G8: =COUNTIFS(V1_Kadro_56!$C$5:$C$60,$A8,V1_Kadro_56!$E$5:$E$60,G$4) -> 1 | H8: =COUNTIFS(V1_Kadro_56!$C$5:$C$60,$A8,V1_Kadro_56!$E$5:$E$60,H$4) -> 1 | I8: =COUNTIFS(V1_Kadro_56!$C$5:$C$60,$A8,V1_Kadro_56!$E$5:$E$60,I$4) -> 1 | ... O8: =COUNTIFS(V1_Kadro_56!$C$5:$C$60,$A8,V1_Kadro_56!$E$5:$E$60,O$4) -> 0 | P8: =SUM(B8:O8) -> 11
A9: Savaşçı | B9: =COUNTIFS(V1_Kadro_56!$C$5:$C$60,$A9,V1_Kadro_56!$E$5:$E$60,B$4) -> 3 | C9: =COUNTIFS(V1_Kadro_56!$C$5:$C$60,$A9,V1_Kadro_56!$E$5:$E$60,C$4) -> 0 | D9: =COUNTIFS(V1_Kadro_56!$C$5:$C$60,$A9,V1_Kadro_56!$E$5:$E$60,D$4) -> 0 | E9: =COUNTIFS(V1_Kadro_56!$C$5:$C$60,$A9,V1_Kadro_56!$E$5:$E$60,E$4) -> 0 | F9: =COUNTIFS(V1_Kadro_56!$C$5:$C$60,$A9,V1_Kadro_56!$E$5:$E$60,F$4) -> 0 | G9: =COUNTIFS(V1_Kadro_56!$C$5:$C$60,$A9,V1_Kadro_56!$E$5:$E$60,G$4) -> 1 | H9: =COUNTIFS(V1_Kadro_56!$C$5:$C$60,$A9,V1_Kadro_56!$E$5:$E$60,H$4) -> 1 | I9: =COUNTIFS(V1_Kadro_56!$C$5:$C$60,$A9,V1_Kadro_56!$E$5:$E$60,I$4) -> 0 | ... O9: =COUNTIFS(V1_Kadro_56!$C$5:$C$60,$A9,V1_Kadro_56!$E$5:$E$60,O$4) -> 2 | P9: =SUM(B9:O9) -> 12
A10: Toplam | B10: =SUM(B5:B9) -> 12 | C10: =SUM(C5:C9) -> 3 | D10: =SUM(D5:D9) -> 4 | E10: =SUM(E5:E9) -> 3 | F10: =SUM(F5:F9) -> 6 | G10: =SUM(G5:G9) -> 4 | H10: =SUM(H5:H9) -> 3 | I10: =SUM(I5:I9) -> 2 | ... P10: =SUM(P5:P9) -> 56

Sheet V1_Irk_Dagilimi
A1: V1 IRK DAĞILIMI
A2: 14 ana ırk sözlüğüne göre V1 toplamları.
A4: Irk | B4: V1 Kart Sayısı | C4: Pay
A5: İnsan | B5: =COUNTIF(V1_Kadro_56!$E$5:$E$60,A5) -> 12 | C5: =B5/56 -> 0.21428571
A6: Elf | B6: =COUNTIF(V1_Kadro_56!$E$5:$E$60,A6) -> 3 | C6: =B6/56 -> 0.053571429
A7: Cüce | B7: =COUNTIF(V1_Kadro_56!$E$5:$E$60,A7) -> 4 | C7: =B7/56 -> 0.071428571
A8: Ejdersoy | B8: =COUNTIF(V1_Kadro_56!$E$5:$E$60,A8) -> 3 | C8: =B8/56 -> 0.053571429
A9: Gölge | B9: =COUNTIF(V1_Kadro_56!$E$5:$E$60,A9) -> 6 | C9: =B9/56 -> 0.10714286
A10: Astral | B10: =COUNTIF(V1_Kadro_56!$E$5:$E$60,A10) -> 4 | C10: =B10/56 -> 0.071428571
A11: Mutant | B11: =COUNTIF(V1_Kadro_56!$E$5:$E$60,A11) -> 3 | C11: =B11/56 -> 0.053571429
A12: Tanrısal | B12: =COUNTIF(V1_Kadro_56!$E$5:$E$60,A12) -> 2 | C12: =B12/56 -> 0.035714286
A13: Sürüngensoy | B13: =COUNTIF(V1_Kadro_56!$E$5:$E$60,A13) -> 3 | C13: =B13/56 -> 0.053571429
A14: Böceksırt | B14: =COUNTIF(V1_Kadro_56!$E$5:$E$60,A14) -> 2 | C14: =B14/56 -> 0.035714286
A15: Canavar | B15: =COUNTIF(V1_Kadro_56!$E$5:$E$60,A15) -> 5 | C15: =B15/56 -> 0.089285714
A16: Ölümsüz | B16: =COUNTIF(V1_Kadro_56!$E$5:$E$60,A16) -> 3 | C16: =B16/56 -> 0.053571429
... A18: Dev | B18: =COUNTIF(V1_Kadro_56!$E$5:$E$60,A18) -> 3 | C18: =B18/56 -> 0.053571429
A19: Toplam | B19: =SUM(B5:B18) -> 56 | C19: =SUM(C5:C18) -> 1

Sheet QA_KONTROL
A1: QA KONTROL PANELİ
A2: Tüm sonuçlar “GEÇTİ” olmalıdır. “HATA” görünürse ilgili kararı yeniden doğrulayın.
A4: Kontrol | B4: Beklenen | C4: Sonuç | D4: Durum
A5: Ana kadro satırı | B5: 56 | C5: =COUNTA(V1_Kadro_56!A5:A60) -> 56 | D5: =IF(C5=56,"GEÇTİ","HATA") -> GEÇTİ
A6: V1 benzersiz ID | B6: 56 | C6: =SUMPRODUCT(1/COUNTIF(V1_Kadro_56!A5:A60,V1_Kadro_56!A5:A60)) -> 56 | D6: =IF(C6=56,"GEÇTİ","HATA") -> GEÇTİ
A7: Yaygın kart | B7: 20 | C7: =COUNTIF(V1_Kadro_56!D5:D60,"Yaygın") -> 20 | D7: =IF(C7=20,"GEÇTİ","HATA") -> GEÇTİ
A8: Nadir kart | B8: 16 | C8: =COUNTIF(V1_Kadro_56!D5:D60,"Nadir") -> 16 | D8: =IF(C8=16,"GEÇTİ","HATA") -> GEÇTİ
A9: Ender kart | B9: 10 | C9: =COUNTIF(V1_Kadro_56!D5:D60,"Ender") -> 10 | D9: =IF(C9=10,"GEÇTİ","HATA") -> GEÇTİ
A10: Efsanevi kart | B10: 5 | C10: =COUNTIF(V1_Kadro_56!D5:D60,"Efsanevi") -> 5 | D10: =IF(C10=5,"GEÇTİ","HATA") -> GEÇTİ
A11: Multi kart | B11: 5 | C11: =COUNTIF(V1_Kadro_56!D5:D60,"Multi") -> 5 | D11: =IF(C11=5,"GEÇTİ","HATA") -> GEÇTİ
A12: V1 üretilecek görsel | B12: 14 | C12: =COUNTIF(V1_Kadro_56!F5:F60,"Üretilecek") -> 0 | D12: =IF(C12=14,"GEÇTİ","HATA") -> HATA
A13: Ana karakter sayısı | B13: 311 | C13: =COUNTA(Tum_Karakterler_311!A2:A312) -> 311 | D13: =IF(C13=311,"GEÇTİ","HATA") -> GEÇTİ
A14: 130 karakteri aşan hikâye | B14: 0 | C14: =COUNTIF(Tum_Karakterler_311!N2:N312,"130 karakteri aşıyor") -> 1 | D14: =IF(C14=0,"GEÇTİ","HATA") -> HATA
A15: ID 192 hikâye uzunluğu | B15: 130 | C15: =INDEX(Tum_Karakterler_311!M2:M312,MATCH(192,Tum_Karakterler_311!A2:A312,0)) -> 130 | D15: =IF(C15<=130,"GEÇTİ","HATA") -> GEÇTİ
A16: Kara_Pence bilinen ad tekrarı | B16: 2 | C16: =COUNTIF(Tum_Karakterler_311!B2:B312,"Kara_Pence") -> 2 | D16: =IF(C16=2,"GEÇTİ","HATA") -> GEÇTİ

Sheet KAYNAK_VE_KURALLAR
A1: KAYNAK VE ÇALIŞMA KURALLARI
A2: Ekip devrinde hangi sayfanın ne için kullanılacağını açıklayan veri sözlüğü.
A4: Sayfa / Kaynak | B4: Rol | C4: Güncelleme Kuralı | D4: Durum
A5: Tum_Karakterler_311 | B5: 311 karakterin tek doğruluk kaynağı | C5: Karakter alanlarını önce burada güncelleyin; ID anahtardır. | D5: Aktif
A6: V1_Kadro_56 | B6: Onaylı V1 seçimi | C6: Yalnızca yönetim kararıyla kadro değiştirin; ardından QA_KONTROL’e bakın. | D6: Aktif
A7: Gorsel_Durum_311 | B7: Tüm proje görsel denetimi | C7: Yeni görsel geldikçe dosya adı, sayı ve durum alanlarını güncelleyin. | D7: Aktif
A8: V1_Uretilecek_14 | B8: Lansman görsel backlog’u | C8: Takip Durumu alanını üretim akışında güncelleyin. | D8: Aktif
A9: Irk_Sozlugu | B9: 14 ana ırk veri sözlüğü | C9: Yeni ana ırk açmayın; alt tür/elementi ırk alanına taşımayın. | D9: Aktif
A10: Sınıf sekmeleri | B10: Ana listenin sınıf bazlı aynaları | C10: Önce ana listeyi, sonra aynı ID satırını güncelleyin. | D10: Ayna
A11: Yetenek sekmeleri | B11: Sınıf yetenek havuzları | C11: Karakter ana verisinden ayrı içerik havuzudur. | D11: Aktif
A12: Gizli teknik sekmeler | B12: Karar ve denge geçmişi | C12: Günlük çalışma için değil; denetim geçmişi için saklanır. | D12: Arşiv

Sheet Gorsel_Durum_311
A1: ID | B1: Karakter | C1: Sınıf | D1: Nadirlik | E1: Yeni Irk | F1: Görsel Sayısı | G1: Görselde Görünen | H1: Durum | I1: Gerekçe | J1: Görsel Dosyaları
A2: 1 | B2: CIRAK_SIFACI | C2: Destek | D2: Yaygın | E2: İnsan | F2: 1 | G2: İnsan görünümlü | H2: Hazır | I2: Görsel morfolojisi yeni ırkla uyumlu. | J2: CIRAK SIFACI.png
A3: 2 | B3: RUH_BEKCISI | C3: Destek | D3: Yaygın | E3: İnsan | F3: 1 | G3: İnsan görünümlü | H3: Hazır | I3: Görsel morfolojisi yeni ırkla uyumlu. | J3: RUH BEKCISI.png
A4: 3 | B4: UMUT_TASIYICI | C4: Destek | D4: Yaygın | E4: İnsan | F4: 1 | G4: İnsan görünümlü | H4: Hazır | I4: Görsel morfolojisi yeni ırkla uyumlu. | J4: UMUT TASIYICI.png
A5: 4 | B5: Sifa_Yildizi | C5: Destek | D5: Yaygın | E5: Elf | F5: 1 | G5: İnsan görünümlü | H5: Hafif düzenleme | I5: Karakter kullanılabilir; ırk işaretleri arka plan, kulak, kanat, doku veya efektle güçlendirilmeli. | J5: Sifa Yildizi.png
A6: 5 | B6: Umut_Alevi | C6: Destek | D6: Yaygın | E6: İnsan | F6: 1 | G6: İnsan görünümlü | H6: Hazır | I6: Görsel morfolojisi yeni ırkla uyumlu. | J6: Umut Alevi.png
A7: 6 | B7: Hayat_Akisi | C7: Destek | D7: Yaygın | E7: Elf | F7: 1 | G7: Elf görünümlü | H7: Hazır | I7: Görsel morfolojisi yeni ırkla uyumlu. | J7: Hayat Akisi.png
A8: 7 | B8: Kutsal_Isik | C8: Destek | D8: Yaygın | E8: Melek | F8: 1 | G8: İnsan görünümlü | H8: Hafif düzenleme | I8: Karakter kullanılabilir; ırk işaretleri arka plan, kulak, kanat, doku veya efektle güçlendirilmeli. | J8: Kutsal Isik.png
A9: 8 | B9: Sonsuz_Sifaci | C9: Destek | D9: Yaygın | E9: Ölümsüz | F9: 1 | G9: İnsan görünümlü | H9: Hazır | I9: Görsel morfolojisi yeni ırkla uyumlu. | J9: Sonsuz Sifaci.png
A10: 9 | B10: Isik_Yoldasi | C10: Destek | D10: Yaygın | E10: İnsan | F10: 1 | G10: İnsan görünümlü | H10: Hazır | I10: Görsel morfolojisi yeni ırkla uyumlu. | J10: Isik Yoldasi.png
A11: 10 | B11: Doga_Efendisi | C11: Destek | D11: Yaygın | E11: Elf | F11: 1 | G11: Elf görünümlü | H11: Hazır | I11: Görsel morfolojisi yeni ırkla uyumlu. | J11: Doga Efendisi.png
A12: 11 | B12: Zihinsel_Sifaci | C12: Destek | D12: Yaygın | E12: İnsan | F12: 1 | G12: İnsan görünümlü | H12: Hazır | I12: Görsel morfolojisi yeni ırkla uyumlu. | J12: Zihinsel Sifaci.png
A13: 12 | B13: Hayat_Koruyucusu | C13: Destek | D13: Yaygın | E13: İnsan | F13: 1 | G13: İnsan görünümlü | H13: Hazır | I13: Kullanıcı tarafından görsel/ırk uyumu doğrulandı. | J13: Hayat Koruyucusu.png
... A56: 55 | B56: Sonsuz_Yasamin_Bekcisi | C56: Destek | D56: Ender | E56: Ölümsüz | F56: 1 | G56: Tam zırhlı, türü belirsiz | H56: Hafif düzenleme | I56: Karakter kullanılabilir; ırk işaretleri arka plan, kulak, kanat, doku veya efektle güçlendirilmeli. | J56: Sonsuz Yasamin Bekcisi.jpg
A57: 56 | B57: Isigin_Yuces | C57: Destek | D57: Ender | E57: Tanrısal | F57: 1 | G57: Görsel mevcut; ırk Tanrısal olarak onaylandı | H57: Hazır | I57: Kullanıcı tarafından görsel/ırk uyumu doğrulandı.
A58: 57 | B58: KADIM_SIFACI | C58: Destek | D58: Efsanevi | E58: Mutant | F58: 0 | H58: Görsel yok | I58: Güvenli eşleşen görsel bulunamadı.
A59: 58 | B59: ISIK_LORDU | C59: Destek | D59: Efsanevi | E59: Melek | F59: 0 | H59: Görsel yok | I59: Güvenli eşleşen görsel bulunamadı.
A60: 59 | B60: YASAM_EFENDISI | C60: Destek | D60: Efsanevi | E60: Astral | F60: 0 | H60: Görsel yok | I60: Güvenli eşleşen görsel bulunamadı.
A61: 60 | B61: Butunlestirici | C61: Destek | D61: Efsanevi | E61: Mutant | F61: 0 | H61: Görsel yok | I61: Güvenli eşleşen görsel bulunamadı.
A62: 61 | B62: IYILESTIRME_TANRISI | C62: Destek | D62: Multi | E62: Tanrısal | F62: 0 | H62: Görsel yok | I62: Güvenli eşleşen görsel bulunamadı.
A63: 62 | B63: YASAM_TANRISI | C63: Destek | D63: Multi | E63: Tanrısal | F63: 0 | H63: Görsel yok | I63: Güvenli eşleşen görsel bulunamadı.
A64: 63 | B64: ZAMAN_BUKUCU | C64: Destek | D64: Multi | E64: Tanrısal | F64: 0 | H64: Görsel yok | I64: Güvenli eşleşen görsel bulunamadı.
A65: 64 | B65: Golge_Ciragi_Golge | C65: Ninja | D65: Yaygın | E65: Gölge | F65: 1 | G65: Gölge/ruh-insansı | H65: Hazır | I65: Görsel morfolojisi yeni ırkla uyumlu. | J65: Gölge Çırağı - Gölge.jpg
A66: 65 | B66: Zehir_Bicagi_Insan | C66: Ninja | D66: Yaygın | E66: Gölge | F66: 1 | G66: İnsan görünümlü | H66: Hafif düzenleme | I66: Karakter kullanılabilir; ırk işaretleri arka plan, kulak, kanat, doku veya efektle güçlendirilmeli. | J66: Zehir Bıçağı - İnsan.jpg
A67: 66 | B67: Hizli_Bicak_Insan | C67: Ninja | D67: Yaygın | E67: Gölge | F67: 1 | G67: İnsan görünümlü | H67: Hafif düzenleme | I67: Karakter kullanılabilir; ırk işaretleri arka plan, kulak, kanat, doku veya efektle güçlendirilmeli. | J67: Hızlı Bıçak - İnsan.jpg
A68: 67 | B68: Golgelerin_Ustasi_Golge | C68: Ninja | D68: Yaygın | E68: Gölge | F68: 1 | G68: Gölge/ruh-insansı | H68: Hazır | I68: Görsel morfolojisi yeni ırkla uyumlu. | J68: Gölgelerin Ustası - Gölge.jpg
A69: 68 | B69: Zehirli_Pence_Golge | C69: Ninja | D69: Yaygın | E69: Gölge | F69: 1 | G69: İnsan görünümlü | H69: Hafif düzenleme | I69: Karakter kullanılabilir; ırk işaretleri arka plan, kulak, kanat, doku veya efektle güçlendirilmeli. | J69: Zehirli Pençe - Gölge.jpg
A70: 69 | B70: Kritik_Golge_Golge | C70: Ninja | D70: Yaygın | E70: Gölge | F70: 1 | G70: İnsan görünümlü | H70: Hafif düzenleme | I70: Karakter kullanılabilir; ırk işaretleri arka plan, kulak, kanat, doku veya efektle güçlendirilmeli. | J70: Kritik Gölge - Gölge.jpg
A71: 70 | B71: Nightmare_Karabasan_Golge | C71: Ninja | D71: Yaygın | E71: Gölge | F71: 1 | G71: Gölge/ruh-insansı | H71: Hazır | I71: Görsel morfolojisi yeni ırkla uyumlu. | J71: Karabasan - Gölge.jpg
A72: 71 | B72: Gizli_Yikici_Cuce | C72: Ninja | D72: Yaygın | E72: Cüce | F72: 1 | G72: Cüce görünümlü | H72: Hazır | I72: Görsel morfolojisi yeni ırkla uyumlu. | J72: Gizli Yıkıcı - Cüce.jpg
A73: 72 | B73: Karanlik_Vekil_Golge | C73: Ninja | D73: Yaygın | E73: Gölge | F73: 1 | G73: Gölge/ruh-insansı | H73: Hazır | I73: Görsel morfolojisi yeni ırkla uyumlu. | J73: Karanlık Vekil - Gölge.jpg
A74: 73 | B74: Sinsi_Safak_Insan | C74: Ninja | D74: Yaygın | E74: Gölge | F74: 1 | G74: İnsan görünümlü | H74: Hafif düzenleme | I74: Karakter kullanılabilir; ırk işaretleri arka plan, kulak, kanat, doku veya efektle güçlendirilmeli. | J74: Şafak Sinsi - İnsan.jpg
A75: 74 | B75: High_Ninja_Insan | C75: Ninja | D75: Yaygın | E75: Gölge | F75: 1 | G75: İnsan görünümlü | H75: Hafif düzenleme | I75: Karakter kullanılabilir; ırk işaretleri arka plan, kulak, kanat, doku veya efektle güçlendirilmeli. | J75: Yüksek Savaşçı - İnsan.jpg
A76: 75 | B76: Gizli_Gozcu_Golge | C76: Ninja | D76: Yaygın | E76: Gölge | F76: 1 | G76: Kapüşonlu/belirsiz insansı | H76: Hafif düzenleme | I76: Karakter kullanılabilir; ırk işaretleri arka plan, kulak, kanat, doku veya efektle güçlendirilmeli. | J76: Gizli Gözcü - Gölge.jpg
... A84: 83 | B84: Mortal_Shadow_Golge | C84: Ninja | D84: Yaygın | E84: Gölge | F84: 1 | G84: Gölge/ruh-insansı | H84: Hazır | I84: Görsel morfolojisi yeni ırkla uyumlu. | J84: Ölümlü Gölge - Gölge.jpg
A85: 84 | B85: Korgoz_Suikastci_Cuce | C85: Ninja | D85: Yaygın | E85: Cüce | F85: 0 | H85: Görsel yok | I85: Güvenli eşleşen görsel bulunamadı.
A86: 85 | B86: Between_The_Shadows_Golge | C86: Ninja | D86: Yaygın | E86: Gölge | F86: 1 | G86: Gölge/ruh-insansı | H86: Hazır | I86: Görsel morfolojisi yeni ırkla uyumlu. | J86: Gölgeler Arasında - Gölge.jpg
A87: 86 | B87: Fisildayan_Hancer_Insan | C87: Ninja | D87: Yaygın | E87: Gölge | F87: 1 | G87: İnsan görünümlü | H87: Hafif düzenleme | I87: Karakter kullanılabilir; ırk işaretleri arka plan, kulak, kanat, doku veya efektle güçlendirilmeli. | J87: Fısıldayan Hançer- İnsan.jpg
A88: 87 | B88: God_Of_Secrecy_Insan | C88: Ninja | D88: Yaygın | E88: Gölge | F88: 1 | G88: İnsan görünümlü | H88: Hafif düzenleme | I88: Karakter kullanılabilir; ırk işaretleri arka plan, kulak, kanat, doku veya efektle güçlendirilmeli. | J88: Gizlilik Tanrısı - İnsan.jpg
A89: 88 | B89: Infinite_Blade_Insan | C89: Ninja | D89: Yaygın | E89: Gölge | F89: 1 | G89: İnsan görünümlü | H89: Hafif düzenleme | I89: Karakter kullanılabilir; ırk işaretleri arka plan, kulak, kanat, doku veya efektle güçlendirilmeli. | J89: Sonsuz Bıçak - İnsan.jpg
...

Sheet Irk_Sozlugu
A1: Ana Irk | B1: Tanım | C1: Alt tür/köken örnekleri | D1: Kural
A2: İnsan | B2: Temel insansı ırk. | C2: Alevsoy, Buzsoy, Arkan, Zaman, Işık vb. köken olabilir. | D2: Meslek, element ve sınıf ırk değildir.
A3: Elf | B3: Tüm elf türlerinin ortak ana ırkı. | C3: Ormanelfi ve Suelfi köken/alt tür olarak saklanabilir. | D3: Ana ırkta yalnızca Elf yazılır.
A4: Cüce | B4: Cüce fiziksel yapısına sahip ırk. | C4: Ocak, dağ veya fırtına kökenleri ayrı alanda tutulur. | D4: Görsel ve isim önceliklidir.
A5: Ejdersoy | B5: Ejderha veya ejder-insansı soy. | C5: Ateş, buz, gölge gibi bağlar element/kökendir. | D5: Ejder görseli güçlü kanıttır.
A6: Gölge | B6: Tüm gölge varlıklarının ortak ırkı. | C6: Gölgedoğan ve Gölge İnsan eski etiketleridir. | D6: Ana ırkta yalnızca Gölge yazılır.
A7: Astral | B7: Kozmik, yıldızsal veya Aether varlıkları. | C7: Yıldızdoğan, Yıldızsoylu, Aetherian köken olabilir. | D7: İnsan görünümlü karakterde görsel ve hikâye birlikte değerlendirilir.
A8: Mutant | B8: Dönüşmüş, deneysel veya fiziksel olarak değişmiş varlık. | C8: Golem/hibrit görünüşler dahil olabilir. | D8: Büyücülerde böcek/ejderimsi özel dönüşümler Mutant olabilir.
A9: Tanrısal | B9: Gerçek ilahi varlık; çok nadir. | C9: Tanrı unvanı tek başına yeterli değildir. | D9: Nadir tutulur, hikâye kanıtı gerekir.
A10: Sürüngensoy | B10: Yılan veya sürüngen temelli varlık. | C10: Boss büyücülerde çok nadir kullanılabilir. | D10: Belirgin sürüngen görünümü gerekir.
A11: Böceksırt | B11: Böcek/araknid bedenli varlık. | C11: Kitin, örümcek ve böcek özellikleri. | D11: Belirgin görsel kanıt gerekir.
A12: Canavar | B12: Hayvansı, minotor, kurt veya aslan-insansı varlık. | C12: Hayvan alt türü ayrıca yazılabilir. | D12: İnsan görünümünde kullanılmaz.
... A15: Dev | B15: Devasa bedenli, titan veya kolos kökenli insansı ırk. | C15: Titan, ağır zırhlı dev ve taş dev kökenleri. | D15: Yalnızca büyük ölçek, isim veya hikâye kanıtı varsa kullanılır.

Sheet Tum_Karakterler_311
A1: ID | B1: Karakter | C1: Sınıf | D1: Nadirlik | E1: Önem Derecesi | F1: Irk | G1: Cinsiyet | H1: Element | I1: Hikâye Düğümü | J1: Bağlantı Karakterleri | K1: Bağlantı Türü | L1: Hikâye | M1: Hikâye Harf Sayısı | N1: 130 Kontrol | O1: Bağlantı Sayısı | P1: Profesyonel Not
A2: 1 | B2: CIRAK_SIFACI | C2: Destek | D2: Yaygın | E2: 1 | F2: İnsan | G2: Kadın | H2: Metal | I2: Demir Cephe | J2: CELIK_KILIC; DEMIR_MUHAFIZ; KIZIL_SAVASCI; Kutsal_Savunma; ATES_CIRAGI; Zehir_Bicagi_Insan; KANLI_GOLGE; Kaya_Bekcisi_hayvan | K2: Destek Ağı | L2: Çelik Kılıç'ı kurtarırken ustasını kaybetti. Artık zafer çığlıklarını değil, yardım isteyemeyen yaralıların sessizliğini dinler. | M2: =LEN(L2) -> 128 | N2: =IF(L2="","Eksik",IF(M2<=130,"Uygun","130 karakteri aşıyor")) -> Uygun | O2: 8 | P2: Açılış yarası; destek sınıfının cepheye ilk gerçek etkisi.
A3: 2 | B3: RUH_BEKCISI | C3: Destek | D3: Yaygın | E3: 1 | F3: İnsan | G3: Erkek | H3: Metal | I3: Ruh Borcu | J3: Olumsuz_Kilic; Demir_Asker_Tanrisal_Olumsuz; Tas_Yurekli_Tanrisal_Olumsuz; KARA_BUYUCUSU; Ruh_Yoneticisi; RUH_BICICI; Immortal_Shadow_golge; OLUMSUZ_KALKANLI_ASKER; Hayalet_Asker | K3: Destek Ağı | L3: Ölümsüz Kılıç'ın ruhunu kendi canına bağladı. Kurtardığı bedenler yaşarken, ölülerin yarım kalan yeminleri uykusunu çalar. | M3: =LEN(L3) -> 122 | N3: =IF(L3="","Eksik",IF(M3<=130,"Uygun","130 karakteri aşıyor")) -> Uygun | O3: 9 | P3: Ölümden sonra bile siyasi/ruhsal borç doğuran bağlantı.
A4: 3 | B4: UMUT_TASIYICI | C4: Destek | D4: Yaygın | E4: 1 | F4: İnsan | G4: Kadın | H4: Savaş | I4: Kutsal Taht | J4: Kutsal_Asker; Kutsal_Zirh; Tacsiz_Muhafiz; KUTSAL_KILIC; ZAFER_MELEGI; GOKYUZU_HAKIMI; ISIK_USTASI; Savunma_Prensesi_Insan; KUTSAL_MUHAFIZ | K4: Destek Ağı | L4: Taht düşerken Kutsal Asker'e yalan söyledi: Yardım geliyor. Şimdi taşıdığı ışık, o sözü gerçeğe dönüştürmek için ettiği yemindir. | M4: =LEN(L4) -> 129 | N4: =IF(L4="","Eksik",IF(M4<=130,"Uygun","130 karakteri aşıyor")) -> Uygun | O4: 9 | P4: Sıradan umut değil, ileride açılacak stratejik yemin.
A5: 4 | B5: Sifa_Yildizi | C5: Destek | D5: Yaygın | E5: 1 | F5: Elf | G5: Kadın | H5: Astral | I5: Yıldız ve Evren Yarığı | J5: Altin_Yildiz; Gok_Yildizi; Galaktik_Bilgisi; Astral_Savunucu; EVREN_BUYUCUSU; EVREN_KORUYUCUSU; Aetherin_Efendisi; BUYU_TANRISI; SAVAS_TANRISI; KAOS_SAMPIYONU | K5: Destek Ağı | L5: Kaybolan kardeşini yıldız haritasında arar. Her şifada bir yıldız söner; kurtardığı canlar eve dönüş yolunu yavaşça siler. | M5: =LEN(L5) -> 122 | N5: =IF(L5="","Eksik",IF(M5<=130,"Uygun","130 karakteri aşıyor")) -> Uygun | O5: 10 | P5: Astral harita üzerinden geri çağırma bağı.
A6: 5 | B6: Umut_Alevi | C6: Destek | D6: Yaygın | E6: 1 | F6: İnsan | G6: Erkek | H6: Ateş | I6: Alev ve Ejder Hattı | J6: Alevli_Savasci; ALEV_KILICI; Atesli_Kilic; Ates_Lordu; Alev_Krali; MAGMA_KORUYUCU; EJDER_PULLU_SOVALYE; Ejderha_Savascisi; Ejderha_Pencesi; ATES_CIRAGI | K6: Destek Ağı | L6: Alev Kılıcı'nın yaktığı köyden son közü kurtardı. İntikam için sakladığı ateş, ilk yaralıyı iyileştirince ona başka bir yol açtı. | M6: =LEN(L6) -> 129 | N6: =IF(L6="","Eksik",IF(M6<=130,"Uygun","130 karakteri aşıyor")) -> Uygun | O6: 10 | P6: Duygusal umut, askeri yasaya dönüşüyor.
A7: 6 | B7: Hayat_Akisi | C7: Destek | D7: Yaygın | E7: 1 | F7: Elf | G7: Kadın | H7: Fırtına | I7: Yaşam ve Ölüm Eşiği | J7: YASAM_TANRISI; IYILESTIRME_TANRISI; OLUM_TANRISI; Sonsuz_Savunma; Kanli_Kalkan; YASAM_EFENDISI; Kadim_Yasam_Efendisi; KADIM_SIFACI; Efsanevi_Iyilestirici; Sonsuz_Yasamin_Bekcisi | K7: Destek Ağı | L7: Nehrini kurtarmak için Ölüm Tanrısı'yla anlaştı. Suları herkese yaşam verir; yalnız içinden yükselen annesinin sesi hiç susmaz. | M7: =LEN(L7) -> 127 | N7: =IF(L7="","Eksik",IF(M7<=130,"Uygun","130 karakteri aşıyor")) -> Uygun | O7: 10 | P7: Yaşam akışı doğrudan tanrısal antlaşmaya bağlanıyor.
A8: 7 | B8: Kutsal_Isik | C8: Destek | D8: Yaygın | E8: 1 | F8: Melek | G8: Erkek | H8: Işık | I8: Kutsal Taht | J8: Kutsal_Asker; Kutsal_Zirh; Tacsiz_Muhafiz; KUTSAL_KILIC; ZAFER_MELEGI; GOKYUZU_HAKIMI; ISIK_USTASI; Savunma_Prensesi_Insan; KUTSAL_MUHAFIZ | K8: Destek Ağı | L8: Kutsal Taht'ın suçlu saydığı çocuğu iyileştirdiği için sürüldü. Kanatları söküldü ama ışığını kimin hak ettiğini kendisi seçer. | M8: =LEN(L8) -> 127 | N8: =IF(L8="","Eksik",IF(M8<=130,"Uygun","130 karakteri aşıyor")) -> Uygun | O8: 9 | P8: Işık, basit iyileştirme değil hüküm seçme aracı.
A9: 8 | B9: Sonsuz_Sifaci | C9: Destek | D9: Yaygın | E9: 1 | F9: Ölümsüz | G9: Kadın | H9: Ateş | I9: Yaşam ve Ölüm Eşiği | J9: YASAM_TANRISI; IYILESTIRME_TANRISI; OLUM_TANRISI; Sonsuz_Savunma; Kanli_Kalkan; YASAM_EFENDISI; Kadim_Yasam_Efendisi; KADIM_SIFACI; Efsanevi_Iyilestirici; Sonsuz_Yasamin_Bekcisi | K9: Destek Ağı | L9: Ölümsüzlüğünü bir köye adadı; köy yüzyıllar önce yok oldu. Şifa verdiği yüzlerde hâlâ ilk hastasının gülüşünü arar. | M9: =LEN(L9) -> 115 | N9: =IF(L9="","Eksik",IF(M9<=130,"Uygun","130 karakteri aşıyor")) -> Uygun | O9: 10 | P9: Şifa her zaman rahatlama değil; görev bedeli yaratıyor.
A10: 9 | B10: Isik_Yoldasi | C10: Destek | D10: Yaygın | E10: 1 | F10: İnsan | G10: Erkek | H10: Işık | I10: Gölge Antlaşması | J10: KARA_SOVALYE; Karanlik_Savasci; Golge_Kalkani; GOLGE_LORDU; GOLGELER_EFENDISI; GOLGE_BUYUCUSU; Zifiri_Buyucu; ABIS_GARDIYANI_golge; Kara_Pence; Kritik_Golge_Golge | K10: Destek Ağı | L10: Kara Şövalye'yi öldürmeye gitti, karanlıkta onunla sağ kaldı. Şimdi ışığı bir düşmanı değil, ikisinin de eve dönüş yolunu korur. | M10: =LEN(L10) -> 128 | N10: =IF(L10="","Eksik",IF(M10<=130,"Uygun","130 karakteri aşıyor")) -> Uygun | O10: 10 | P10: Işık-gölge geçişini kuran ara düğüm.
A11: 10 | B11: Doga_Efendisi | C11: Destek | D11: Yaygın | E11: 1 | F11: Elf | G11: Erkek | H11: Enerji | I11: Doğa ve Zirve Geçidi | J11: Zirve_Pencesi; Zirve_Kilici; Zirve_Efendisi; Kaya_Bekcisi_hayvan; Kum_Zirhli_Cuce; Gece_Yilani_Surungensoy; Vahsi_Elementalist; DOVUS_USTASI; Zirhli_Dev_Ejdersoy | K11: Destek Ağı | L11: Zirve Geçidi'ni köklerle mühürledi; ardında kendi halkı da kaldı. Ormanı koruyan her dal, bir gün yüzleşeceği o kararı hatırlatır. | M11: =LEN(L11) -> 130 | N11: =IF(L11="","Eksik",IF(M11<=130,"Uygun","130 karakteri aşıyor")) -> Uygun | O11: 9 | P11: Doğa, pasif ortam değil stratejik savunma alanı.
A12: 11 | B12: Zihinsel_Sifaci | C12: Destek | D12: Yaygın | E12: 1 | F12: İnsan | G12: Kadın | H12: Gölge | I12: Zihin ve Felsefe Mahkemesi | J12: Felsefe_Buyucusu; Yuce_Akil; Korku_Imparatoru_golge; Korgoz_Suikastci_Cuce; Buyuk_Tehlike; Karanlik_Kader; Kader_Orgusu_Arkan_buyucusu; SAVAS_TANRISI | K12: Destek Ağı | L12: Yüce Akıl'ın zihnini onardı, korkunç sırrını öğrendi. Hastasını koruma yeminiyle dünyayı uyarma isteği arasında anılarını siler. | M12: =LEN(L12) -> 128 | N12: =IF(L12="","Eksik",IF(M12<=130,"Uygun","130 karakteri aşıyor")) -> Uygun | O12: 8 | P12: Şifa edilen sır, başka bir karakterin silahına dönüşüyor.
A13: 12 | B13: Hayat_Koruyucusu | C13: Destek | D13: Yaygın | E13: 1 | F13: İnsan | G13: Erkek | H13: Metal | I13: Yaşam ve Ölüm Eşiği | J13: YASAM_TANRISI; IYILESTIRME_TANRISI; OLUM_TANRISI; Sonsuz_Savunma; Kanli_Kalkan; YASAM_EFENDISI; Kadim_Yasam_Efendisi; KADIM_SIFACI; Efsanevi_Iyilestirici; Sonsuz_Yasamin_Bekcisi | K13: Destek Ağı | L13: Kanlı Kalkan'ın ardında son nefesi sakladı. Ölüm onu geri istediğinde, bir yabancı uğruna kendi ömrünü masaya koydu. | M13: =LEN(L13) -> 116 | N13: =IF(L13="","Eksik",IF(M13<=130,"Uygun","130 karakteri aşıyor")) -> Uygun | O13: 10 | P13: Bir nefes, kraliyet ve yaşam hattı arasında mirasa dönüşüyor.
... A16: 15 | B16: Efsanevi_Sifaci | C16: Destek | D16: Yaygın | E16: 1 | F16: İnsan | G16: Kadın | H16: Savaş | I16: Demir Cephe | J16: CELIK_KILIC; DEMIR_MUHAFIZ; KIZIL_SAVASCI; Kutsal_Savunma; ATES_CIRAGI; Zehir_Bicagi_Insan; KANLI_GOLGE; Kaya_Bekcisi_hayvan | K16: Destek Ağı | L16: Demir Cephe'nin kahramanı ilan edildi. Kurtardığı komutan savaşı uzatınca, şifanın da bazen bir silaha dönüşebildiğini öğrendi. | M16: =LEN(L16) -> 127 | N16: =IF(L16="","Eksik",IF(M16<=130,"Uygun","130 karakteri aşıyor")) -> Uygun | O16: 8 | P16: Ucuz kurtuluş yerine karakter gelişimi bedeli.
A17: 16 | B17: Hayat_Rehberi | C17: Destek | D17: Yaygın | E17: 1 | F17: İnsan | G17: Erkek | H17: Ateş | I17: Kutsal Taht | J17: Kutsal_Asker; Kutsal_Zirh; Tacsiz_Muhafiz; KUTSAL_KILIC; ZAFER_MELEGI; GOKYUZU_HAKIMI; ISIK_USTASI; Savunma_Prensesi_Insan; KUTSAL_MUHAFIZ | K17: Destek Ağı | L17: Taçsız Muhafız'a gizli kaçış yolunu gösterdi; hükümdar dönmeyince halkın karşısına çıktı. Artık kimseyi ardında bırakmadan yürür. | M17: 129 | N17: Uygun | O17: 9 | P17: Savaş liderinin otoritesini destek bilgeliğine bağlar.
A18: 17 | B18: Evren_Sifacisi | C18: Destek | D18: Yaygın | E18: 1 | F18: Astral | G18: Kadın | H18: Astral | I18: Yıldız ve Evren Yarığı | J18: Altin_Yildiz; Gok_Yildizi; Galaktik_Bilgisi; Astral_Savunucu; EVREN_BUYUCUSU; EVREN_KORUYUCUSU; Aetherin_Efendisi; BUYU_TANRISI; SAVAS_TANRISI; KAOS_SAMPIYONU | K18: Destek Ağı | L18: Evrenin yarığını kapatınca kayıp bir dünyanın sesini duydu. Şifasını durdurursa halkı ölecek, sürdürürse o ses ebediyen susacak. | M18: =LEN(L18) -> 128 | N18: =IF(L18="","Eksik",IF(M18<=130,"Uygun","130 karakteri aşıyor")) -> Uygun | O18: 10 | P18: Kozmik ölçekte şifa, gizli bilgi gerilimi yaratıyor.
A19: 18 | B19: Isik_Vekili | C19: Destek | D19: Yaygın | E19: 1 | F19: Melek | G19: Erkek | H19: Işık | I19: Gölge Antlaşması | J19: KARA_SOVALYE; Karanlik_Savasci; Golge_Kalkani; GOLGE_LORDU; GOLGELER_EFENDISI; GOLGE_BUYUCUSU; Zifiri_Buyucu; ABIS_GARDIYANI_golge; Kara_Pence; Kritik_Golge_Golge | K19: Destek Ağı | L19: Gölge Lordu'yla çizdiği sınır, bir aileyi ikiye böldü. Işığını şimdi antlaşmayı korumak için değil, onları buluşturmak için taşır. | M19: =LEN(L19) -> 130 | N19: =IF(L19="","Eksik",IF(M19<=130,"Uygun","130 karakteri aşıyor")) -> Uygun | O19: 10 | P19: Yok etme değil, diplomatik/sihirsel sınır koyma.
A20: 19 | B20: Mistik_Sifaci | C20: Destek | D20: Yaygın | E20: 1 | F20: İnsan | G20: Kadın | H20: Arkan | I20: Zaman ve Arkan Kırığı | J20: Zaman_Efendisi; ZAMAN_BUYUCUSU; Kader_Orgusu_Arkan_buyucusu; BOYUT_USTASI_bukucu; BOYUT_KATILI; KIYAMET_BUYUCUSU; Kiyamet_Askeri; SAVAS_LORDU; Kehanetci; Buyuk_Arcana | K20: Destek Ağı | L20: Büyük Arcana'nın kartında iyileştireceği yarayı gördü. Her kurtarışta kehanet değişir; son kartta artık yalnız kendi adı vardır. | M20: =LEN(L20) -> 128 | N20: =IF(L20="","Eksik",IF(M20<=130,"Uygun","130 karakteri aşıyor")) -> Uygun | O20: 10 | P20: Kart/kehanet hattı; sonraki büyücü bağlarını hazırlar.
A21: 20 | B21: Hayat_Fisildayicisi | C21: Destek | D21: Yaygın | E21: 1 | F21: Elf | G21: Kadın | H21: Zehir | I21: Zehir ve Gizli Savaş | J21: Zehir_Bicagi_Insan; Zehirli_Ruya; Zehirli_Intikamci; Poisoned_Knife_Insan; Gece_Yilani_Surungensoy; Kara_Pence; Kritik_Kara_Pence_Golge; Yikici_Sovalye | K21: Destek Ağı | L21: Gece Yılanı'nın zehirlediği ağacı dinledi; kökler katilin adını fısıldadı. Ormanı iyileştirmek için önce onu yaşatması gerek. | M21: =LEN(L21) -> 125 | N21: =IF(L21="","Eksik",IF(M21<=130,"Uygun","130 karakteri aşıyor")) -> Uygun | O21: 8 | P21: Zehirle doğa arasında gizli karşı-ritüel.
A22: 21 | B22: Kadim_Ruh_Samani | C22: Destek | D22: Yaygın | E22: 1 | F22: Astral | G22: Erkek | H22: Metal | I22: Ruh Borcu | J22: Olumsuz_Kilic; Demir_Asker_Tanrisal_Olumsuz; Tas_Yurekli_Tanrisal_Olumsuz; KARA_BUYUCUSU; Ruh_Yoneticisi; RUH_BICICI; Immortal_Shadow_golge; OLUMSUZ_KALKANLI_ASKER; Hayalet_Asker | K22: Destek Ağı | L22: Ruh Yöneticisi'nden atalarının sesini geri aldı. İçlerinden biri hainin adını söyleyince, kutsal soyun yalanını öğrendi. | M22: =LEN(L22) -> 120 | N22: =IF(L22="","Eksik",IF(M22<=130,"Uygun","130 karakteri aşıyor")) -> Uygun | O22: 9 | P22: Eski güç ile büyücü sınıfı arasında ağır sır.
A23: 22 | B23: Isigin_Efendisi | C23: Destek | D23: Yaygın | E23: 1 | F23: Elf | G23: Erkek | H23: Kaos | I23: Kutsal Taht | J23: Kutsal_Asker; Kutsal_Zirh; Tacsiz_Muhafiz; KUTSAL_KILIC; ZAFER_MELEGI; GOKYUZU_HAKIMI; ISIK_USTASI; Savunma_Prensesi_Insan; KUTSAL_MUHAFIZ | K23: Destek Ağı | L23: Gökyüzü Hâkimi'nin ışığını ödünç aldı. Her şifa kanadından bir tüy yakar; yere düşmeden kurtarmak istediği son kişi düşmanıdır. | M23: =LEN(L23) -> 127 | N23: =IF(L23="","Eksik",IF(M23<=130,"Uygun","130 karakteri aşıyor")) -> Uygun | O23: 9 | P23: Göksel otoriteye bedel fikri ekleniyor.
A24: 23 | B24: Hayat_Armonisti | C24: Destek | D24: Yaygın | E24: 1 | F24: Elf | G24: Kadın | H24: Fırtına | I24: Fırtına Hattı | J24: Firtina_Celik; Simsek_Askeri; FIRTINA_DOVUSCUSU; Yildirim_Muhafizi; Ruzgar_Efendisi; YILDIRIM_ADEPTI; Kritik_Firtina_INSAN; Firtina_Yikici; Firtina_Aslani; Firtina_Efendisi | K24: Destek Ağı | L24: Şimşek Askeri'nin bozulan kalp ritmine bir ezgi yazdı. Savaş bitince şarkıyı susturamadı; o kalp artık yalnız sesiyle atar. | M24: =LEN(L24) -> 123 | N24: =IF(L24="","Eksik",IF(M24<=130,"Uygun","130 karakteri aşıyor")) -> Uygun | O24: 10 | P24: Savaş temposu ve destek ritmi arasında profesyonel bağ.
A25: 24 | B25: Zamanin_Yoldasi | C25: Destek | D25: Yaygın | E25: 1 | F25: Astral | G25: Erkek | H25: Zaman | I25: Zaman ve Arkan Kırığı | J25: Zaman_Efendisi; ZAMAN_BUYUCUSU; Kader_Orgusu_Arkan_buyucusu; BOYUT_USTASI_bukucu; BOYUT_KATILI; KIYAMET_BUYUCUSU; Kiyamet_Askeri; SAVAS_LORDU; Kehanetci; Buyuk_Arcana | K25: Destek Ağı | L25: Zaman Efendisi'nin kırık saatini saklar. Dostlarına kazandırdığı her saniye, evde bekleyenlerin ömründen sessizce eksilir. | M25: =LEN(L25) -> 122 | N25: =IF(L25="","Eksik",IF(M25<=130,"Uygun","130 karakteri aşıyor")) -> Uygun | O25: 10 | P25: Zaman nesnesi üzerinden ninja/büyücü geçişi.
A26: 25 | B26: Kutsal_Sifaci | C26: Destek | D26: Yaygın | E26: 1 | F26: İnsan | G26: Kadın | H26: Gölge | I26: Kutsal Taht | J26: Kutsal_Asker; Kutsal_Zirh; Tacsiz_Muhafiz; KUTSAL_KILIC; ZAFER_MELEGI; GOKYUZU_HAKIMI; ISIK_USTASI; Savunma_Prensesi_Insan; KUTSAL_MUHAFIZ | K26: Destek Ağı | L26: Kutsal Taht'ın idam ettiği askeri diriltti. Hem cellatlar hem kurtardığı can peşinde; mezardan dönen kişi gerçeği hatırlıyor. | M26: =LEN(L26) -> 125 | N26: =IF(L26="","Eksik",IF(M26<=130,"Uygun","130 karakteri aşıyor")) -> Uygun | O26: 9 | P26: Şifa ahlakî mahkemeye dönüşüyor.
A27: 26 | B27: Evrenin_Korumacisi | C27: Destek | D27: Yaygın | E27: 1 | F27: Astral | G27: Erkek | H27: Astral | I27: Yıldız ve Evren Yarığı | J27: Altin_Yildiz; Gok_Yildizi; Galaktik_Bilgisi; Astral_Savunucu; EVREN_BUYUCUSU; EVREN_KORUYUCUSU; Aetherin_Efendisi; BUYU_TANRISI; SAVAS_TANRISI; KAOS_SAMPIYONU | K27: Destek Ağı | L27: Astral Savunucu'nun zırhındaki yarığı onardı. İçine sığınan kayıp yıldızı korumak için göğün bütün yasalarına karşı durur. | M27: =LEN(L27) -> 122 | N27: =IF(L27="","Eksik",IF(M27<=130,"Uygun","130 karakteri aşıyor")) -> Uygun | O27: 10 | P27: Zırh tamiri değil, kozmik yasa onarımı.
A28: 27 | B28: Yasamin_Bekcisi | C28: Destek | D28: Yaygın | E28: 1 | F28: Elf | G28: Kadın | H28: Fırtına | I28: Yaşam ve Ölüm Eşiği | J28: YASAM_TANRISI; IYILESTIRME_TANRISI; OLUM_TANRISI; Sonsuz_Savunma; Kanli_Kalkan; YASAM_EFENDISI; Kadim_Yasam_Efendisi; KADIM_SIFACI; Efsanevi_Iyilestirici; Sonsuz_Yasamin_Bekcisi | K28: Destek Ağı | L28: Ölümle yaşamın eşiğinde adları kontrol eder. Bir gün listede kendi adını buldu; kalemi kırıp nöbetini bırakmamayı seçti. | M28: =LEN(L28) -> 120 | N28: =IF(L28="","Eksik",IF(M28<=130,"Uygun","130 karakteri aşıyor")) -> Uygun | O28: 10 | P28: Yaşam/ölüm dengesini tanrısal protokole bağlar.
A29: 28 | B29: Felsefe_Sifacisi | C29: Destek | D29: Yaygın | E29: 1 | F29: İnsan | G29: Erkek | H29: Arkan | I29: Zihin ve Felsefe Mahkemesi | J29: Felsefe_Buyucusu; Yuce_Akil; Korku_Imparatoru_golge; Korgoz_Suikastci_Cuce; Buyuk_Tehlike; Karanlik_Kader; Kader_Orgusu_Arkan_buyucusu; SAVAS_TANRISI | K29: Destek Ağı | L29: Felsefe Büyücüsü acının gereksiz olduğunu söyledi. Onu iyileştirince merhameti de kayboldu; şimdi sildiği yarayı geri arıyor. | M29: =LEN(L29) -> 125 | N29: =IF(L29="","Eksik",IF(M29<=130,"Uygun","130 karakteri aşıyor")) -> Uygun | O29: 8 | P29: Düşünsel güç savaş gücünden üstün bir an kazanır.
... A41: 40 | B41: Sonsuz_Umut | C41: Destek | D41: Nadir | E41: 2 | F41: Melek | G41: Kadın | H41: Fırtına | I41: Kutsal Taht | J41: Kutsal_Asker; Kutsal_Zirh; Tacsiz_Muhafiz; KUTSAL_KILIC; ZAFER_MELEGI; GOKYUZU_HAKIMI; ISIK_USTASI; Savunma_Prensesi_Insan; KUTSAL_MUHAFIZ | K41: Destek Ağı | L41: Kutsal Taht'ın zafer defterine ölenlerin adını yazdı. Her iyileştirdiği askere aynı sözü verir: Seni kimse tarihten silemeyecek. | M41: =LEN(L41) -> 128 | N41: =IF(L41="","Eksik",IF(M41<=130,"Uygun","130 karakteri aşıyor")) -> Uygun | O41: 9 | P41: Zafer propagandasına karşı etik kayıt.
A42: 41 | B42: Isigin_Murekkep | C42: Destek | D42: Nadir | E42: 2 | F42: İnsan | G42: Erkek | H42: Arkan | I42: Kutsal Taht | J42: Kutsal_Asker; Kutsal_Zirh; Tacsiz_Muhafiz; KUTSAL_KILIC; ZAFER_MELEGI; GOKYUZU_HAKIMI; ISIK_USTASI; Savunma_Prensesi_Insan; KUTSAL_MUHAFIZ | K42: Destek Ağı | L42: Taçsız Muhafız'ın yemininin altına adını yazdı. Hükümdar sözünü her bozduğunda mürekkep derisini yakar; yine de defteri saklar. | M42: 127 | N42: Uygun | O42: 9 | P42: Yazı/ferman üzerinden taht hukukunu kurar.
A43: 42 | B43: Mistik_Hayat | C43: Destek | D43: Nadir | E43: 2 | F43: Elf | G43: Kadın | H43: Arkan | I43: Zehir ve Gizli Savaş | J43: Zehir_Bicagi_Insan; Zehirli_Ruya; Zehirli_Intikamci; Poisoned_Knife_Insan; Gece_Yilani_Surungensoy; Kara_Pence; Kritik_Kara_Pence_Golge; Yikici_Sovalye | K43: Destek Ağı | L43: Zehirli Rüya'da bir çocuğun geleceğini gördü. Onu iyileştirirse felaket doğacak; şifacı elleri bir yaraya uzanırken titrer. | M43: =LEN(L43) -> 123 | N43: =IF(L43="","Eksik",IF(M43<=130,"Uygun","130 karakteri aşıyor")) -> Uygun | O43: 8 | P43: Kötü etkiyi silmek yerine kehanete dönüştürür.
A44: 43 | B44: Kadim_Ruh_Koruyucusu | C44: Destek | D44: Nadir | E44: 2 | F44: Astral | G44: Erkek | H44: Kaos | I44: Kaos ve Kıyamet Düğümü | J44: KIYAMET_SAVASCISI; KIYAMET_BUYUCUSU; KIYAMET_SUIKASTCISI; Kiyamet_Askeri; KAOS_GOLGESI; Karanlik_Kader; Yikim_Tanrisi; Yikim_Avcisi; Yikici_Sovalye; EFSANE_GLADYATOR | K44: Destek Ağı | L44: Kaos Gölgesi'ni atalarının ruhlarıyla mühürledi. Mührü her yenilediğinde bir atası unutulur; sonuncusu kendi adını fısıldıyor. | M44: =LEN(L44) -> 126 | N44: =IF(L44="","Eksik",IF(M44<=130,"Uygun","130 karakteri aşıyor")) -> Uygun | O44: 10 | P44: Bir tehdidi durdurmak daha büyük tehdidi uyandırır.
A45: 44 | B45: Yasamin_Isigi | C45: Destek | D45: Nadir | E45: 2 | F45: İnsan | G45: Kadın | H45: Gölge | I45: Demir Cephe | J45: CELIK_KILIC; DEMIR_MUHAFIZ; KIZIL_SAVASCI; Kutsal_Savunma; ATES_CIRAGI; Zehir_Bicagi_Insan; KANLI_GOLGE; Kaya_Bekcisi_hayvan | K45: Destek Ağı | L45: Kanlı Gölge'nin izini yaralılarda buldu. Komutanının katil olduğunu görünce, ışığını saklanan bir suçu açmakta kullandı. | M45: =LEN(L45) -> 120 | N45: =IF(L45="","Eksik",IF(M45<=130,"Uygun","130 karakteri aşıyor")) -> Uygun | O45: 8 | P45: Kanlı motif adalet filtresine dönüşür.
A46: 45 | B46: Mistik_Yoldas | C46: Destek | D46: Nadir | E46: 2 | F46: Astral | G46: Erkek | H46: Arkan | I46: Zaman ve Arkan Kırığı | J46: Zaman_Efendisi; ZAMAN_BUYUCUSU; Kader_Orgusu_Arkan_buyucusu; BOYUT_USTASI_bukucu; BOYUT_KATILI; KIYAMET_BUYUCUSU; Kiyamet_Askeri; SAVAS_LORDU; Kehanetci; Buyuk_Arcana | K46: Destek Ağı | L46: Boyut Katili'yle geçtiği kapıda adını yitirdi. Dostları onu her sabah unutur; o, her gece aynı canları yeniden korumayı seçer. | M46: =LEN(L46) -> 126 | N46: =IF(L46="","Eksik",IF(M46<=130,"Uygun","130 karakteri aşıyor")) -> Uygun | O46: 10 | P46: Geçit bilgisi suikastçının kendi avına dönüşür.
A47: 46 | B47: Evrenin_Iyilestiricisi | C47: Destek | D47: Nadir | E47: 2 | F47: Astral | G47: Kadın | H47: Astral | I47: Yıldız ve Evren Yarığı | J47: Altin_Yildiz; Gok_Yildizi; Galaktik_Bilgisi; Astral_Savunucu; EVREN_BUYUCUSU; EVREN_KORUYUCUSU; Aetherin_Efendisi; BUYU_TANRISI; SAVAS_TANRISI; KAOS_SAMPIYONU | K47: Destek Ağı | L47: Evren Büyücüsü'nün yarığını yıldızlarla dikti. Dikişin ötesinde ailesi kaldı; evreni iyileştiren elleri o yarayı açmayı da bilir. | M47: =LEN(L47) -> 129 | N47: =IF(L47="","Eksik",IF(M47<=130,"Uygun","130 karakteri aşıyor")) -> Uygun | O47: 10 | P47: Kapanmayan yara, evren haritasında sınır olur.
A48: 47 | B48: Isigin_Yukselisi | C48: Destek | D48: Nadir | E48: 2 | F48: İnsan | G48: Erkek | H48: Gölge | I48: Gölge Antlaşması | J48: KARA_SOVALYE; Karanlik_Savasci; Golge_Kalkani; GOLGE_LORDU; GOLGELER_EFENDISI; GOLGE_BUYUCUSU; Zifiri_Buyucu; ABIS_GARDIYANI_golge; Kara_Pence; Kritik_Golge_Golge | K48: Destek Ağı | L48: Kara Şövalye'nin zırhında annesinin duasını buldu. Düşmanını iyileştirdiği gün öğrendi: Işık, hep doğru taraftan yükselmiyordu. | M48: =LEN(L48) -> 127 | N48: =IF(L48="","Eksik",IF(M48<=130,"Uygun","130 karakteri aşıyor")) -> Uygun | O48: 10 | P48: Düşmanı yok etmek yerine gizli yemini açığa çıkarır.
A49: 48 | B49: Tanrisal_Sifaci | C49: Destek | D49: Nadir | E49: 2 | F49: Tanrısal | G49: Nötr | H49: Buz | I49: Yaşam ve Ölüm Eşiği | J49: YASAM_TANRISI; IYILESTIRME_TANRISI; OLUM_TANRISI; Sonsuz_Savunma; Kanli_Kalkan; YASAM_EFENDISI; Kadim_Yasam_Efendisi; KADIM_SIFACI; Efsanevi_Iyilestirici; Sonsuz_Yasamin_Bekcisi | K49: Destek Ağı | L49: Ölüm Tanrısı'ndan bir canı geri aldı. Mucize isteyenler kapısına yığılırken o, dönen kişinin gözlerinde eksilen şeyi arar. | M49: =LEN(L49) -> 122 | N49: =IF(L49="","Eksik",IF(M49<=130,"Uygun","130 karakteri aşıyor")) -> Uygun | O49: 10 | P49: Tanrısal gücü ölümlü sesine bağlayan kritik düğüm.
A50: 49 | B50: ZAMAN_SIFACISI | C50: Destek | D50: Ender | E50: 3 | F50: İnsan | G50: Kadın | H50: Gölge | I50: Zaman ve Arkan Kırığı | J50: Zaman_Efendisi; ZAMAN_BUYUCUSU; Kader_Orgusu_Arkan_buyucusu; BOYUT_USTASI_bukucu; BOYUT_KATILI; KIYAMET_BUYUCUSU; Kiyamet_Askeri; SAVAS_LORDU; Kehanetci; Buyuk_Arcana | K50: Destek Ağı | L50: Kıyamet'in vurduğu anı geri sardı. Herkes kurtuldu ama onu seven kişi hiç tanışmadıklarını söylüyor; yeni geleceğin bedeli budur. | M50: =LEN(L50) -> 129 | N50: =IF(L50="","Eksik",IF(M50<=130,"Uygun","130 karakteri aşıyor")) -> Uygun | O50: 10 | P50: Zaman üstü onarım; Multi seviyesine doğrudan köprü.
A51: 50 | B51: RUH_SAMANI | C51: Destek | D51: Ender | E51: 3 | F51: İnsan | G51: Erkek | H51: Gölge | I51: Gölge Antlaşması | J51: KARA_SOVALYE; Karanlik_Savasci; Golge_Kalkani; GOLGE_LORDU; GOLGELER_EFENDISI; GOLGE_BUYUCUSU; Zifiri_Buyucu; ABIS_GARDIYANI_golge; Kara_Pence; Kritik_Golge_Golge | K51: Destek Ağı | L51: Gölge Lordu'yla ölüleri almak için anlaştı. Çağırdığı her ruh kalkanını güçlendirir; karşılığında bir anısını gölgeye bırakır. | M51: =LEN(L51) -> 126 | N51: =IF(L51="","Eksik",IF(M51<=130,"Uygun","130 karakteri aşıyor")) -> Uygun | O51: 10 | P51: Gölge lordluğu ile ruh bedeli arasında ağır pazarlık.
A52: 51 | B52: YASAM_USTASI | C52: Destek | D52: Ender | E52: 3 | F52: İnsan | G52: Kadın | H52: Kaos | I52: Yaşam ve Ölüm Eşiği | J52: YASAM_TANRISI; IYILESTIRME_TANRISI; OLUM_TANRISI; Sonsuz_Savunma; Kanli_Kalkan; YASAM_EFENDISI; Kadim_Yasam_Efendisi; KADIM_SIFACI; Efsanevi_Iyilestirici; Sonsuz_Yasamin_Bekcisi | K52: Destek Ağı | L52: Yaşamla ölüm arasında canları paylaştırmayı öğrendi. En sevdiği kişiyi kurtaracak güç elindeyken, denge ondan vazgeçmesini istedi. | M52: =LEN(L52) -> 130 | N52: =IF(L52="","Eksik",IF(M52<=130,"Uygun","130 karakteri aşıyor")) -> Uygun | O52: 10 | P52: Zafer yerine kozmik müzakere kurar.
A53: 52 | B53: Zamanin_Rehberi | C53: Destek | D53: Ender | E53: 3 | F53: İnsan | G53: Erkek | H53: Kaos | I53: Kaos ve Kıyamet Düğümü | J53: KIYAMET_SAVASCISI; KIYAMET_BUYUCUSU; KIYAMET_SUIKASTCISI; Kiyamet_Askeri; KAOS_GOLGESI; Karanlik_Kader; Yikim_Tanrisi; Yikim_Avcisi; Yikici_Sovalye; EFSANE_GLADYATOR | K53: Destek Ağı | L53: Kıyamet Savaşçısı'na son saniyeyi gösterdi. Her gelecekte dünya kurtuluyordu; hiçbirinde kahramanın eve döndüğünü söylemedi. | M53: =LEN(L53) -> 124 | N53: =IF(L53="","Eksik",IF(M53<=130,"Uygun","130 karakteri aşıyor")) -> Uygun | O53: 10 | P53: Kahramanı kaçıştan alıp seçim noktasına zorlar.
...

Sheet Destek
A1: ID | B1: Karakter | C1: Sınıf | D1: Nadirlik | E1: Önem Derecesi | F1: Irk | G1: Cinsiyet | H1: Element | I1: Hikâye Düğümü | J1: Bağlantı Karakterleri | K1: Bağlantı Türü | L1: Hikâye | M1: Hikâye Harf Sayısı | N1: 130 Kontrol | O1: Bağlantı Sayısı | P1: Profesyonel Not
A2: 1 | B2: CIRAK_SIFACI | C2: Destek | D2: Yaygın | E2: 1 | F2: İnsan | G2: Kadın | H2: Metal | I2: Demir Cephe | J2: CELIK_KILIC; DEMIR_MUHAFIZ; KIZIL_SAVASCI; Kutsal_Savunma; ATES_CIRAGI; Zehir_Bicagi_Insan; KANLI_GOLGE; Kaya_Bekcisi_hayvan | K2: Destek Ağı | L2: Çelik Kılıç'ı kurtarırken ustasını kaybetti. Artık zafer çığlıklarını değil, yardım isteyemeyen yaralıların sessizliğini dinler. | M2: =LEN(L2) -> 128 | N2: =IF(L2="","Eksik",IF(M2<=130,"Uygun","130 karakteri aşıyor")) -> Uygun | O2: 8 | P2: Açılış yarası; destek sınıfının cepheye ilk gerçek etkisi.
A3: 2 | B3: RUH_BEKCISI | C3: Destek | D3: Yaygın | E3: 1 | F3: İnsan | G3: Erkek | H3: Metal | I3: Ruh Borcu | J3: Olumsuz_Kilic; Demir_Asker_Tanrisal_Olumsuz; Tas_Yurekli_Tanrisal_Olumsuz; KARA_BUYUCUSU; Ruh_Yoneticisi; RUH_BICICI; Immortal_Shadow_golge; OLUMSUZ_KALKANLI_ASKER; Hayalet_Asker | K3: Destek Ağı | L3: Ölümsüz Kılıç'ın ruhunu kendi canına bağladı. Kurtardığı bedenler yaşarken, ölülerin yarım kalan yeminleri uykusunu çalar. | M3: =LEN(L3) -> 122 | N3: =IF(L3="","Eksik",IF(M3<=130,"Uygun","130 karakteri aşıyor")) -> Uygun | O3: 9 | P3: Ölümden sonra bile siyasi/ruhsal borç doğuran bağlantı.
A4: 3 | B4: UMUT_TASIYICI | C4: Destek | D4: Yaygın | E4: 1 | F4: İnsan | G4: Kadın | H4: Savaş | I4: Kutsal Taht | J4: Kutsal_Asker; Kutsal_Zirh; Tacsiz_Muhafiz; KUTSAL_KILIC; ZAFER_MELEGI; GOKYUZU_HAKIMI; ISIK_USTASI; Savunma_Prensesi_Insan; KUTSAL_MUHAFIZ | K4: Destek Ağı | L4: Taht düşerken Kutsal Asker'e yalan söyledi: Yardım geliyor. Şimdi taşıdığı ışık, o sözü gerçeğe dönüştürmek için ettiği yemindir. | M4: =LEN(L4) -> 129 | N4: =IF(L4="","Eksik",IF(M4<=130,"Uygun","130 karakteri aşıyor")) -> Uygun | O4: 9 | P4: Sıradan umut değil, ileride açılacak stratejik yemin.
A5: 4 | B5: Sifa_Yildizi | C5: Destek | D5: Yaygın | E5: 1 | F5: Elf | G5: Kadın | H5: Astral | I5: Yıldız ve Evren Yarığı | J5: Altin_Yildiz; Gok_Yildizi; Galaktik_Bilgisi; Astral_Savunucu; EVREN_BUYUCUSU; EVREN_KORUYUCUSU; Aetherin_Efendisi; BUYU_TANRISI; SAVAS_TANRISI; KAOS_SAMPIYONU | K5: Destek Ağı | L5: Kaybolan kardeşini yıldız haritasında arar. Her şifada bir yıldız söner; kurtardığı canlar eve dönüş yolunu yavaşça siler. | M5: =LEN(L5) -> 122 | N5: =IF(L5="","Eksik",IF(M5<=130,"Uygun","130 karakteri aşıyor")) -> Uygun | O5: 10 | P5: Astral harita üzerinden geri çağırma bağı.
A6: 5 | B6: Umut_Alevi | C6: Destek | D6: Yaygın | E6: 1 | F6: İnsan | G6: Erkek | H6: Ateş | I6: Alev ve Ejder Hattı | J6: Alevli_Savasci; ALEV_KILICI; Atesli_Kilic; Ates_Lordu; Alev_Krali; MAGMA_KORUYUCU; EJDER_PULLU_SOVALYE; Ejderha_Savascisi; Ejderha_Pencesi; ATES_CIRAGI | K6: Destek Ağı | L6: Alev Kılıcı'nın yaktığı köyden son közü kurtardı. İntikam için sakladığı ateş, ilk yaralıyı iyileştirince ona başka bir yol açtı. | M6: =LEN(L6) -> 129 | N6: =IF(L6="","Eksik",IF(M6<=130,"Uygun","130 karakteri aşıyor")) -> Uygun | O6: 10 | P6: Duygusal umut, askeri yasaya dönüşüyor.
A7: 6 | B7: Hayat_Akisi | C7: Destek | D7: Yaygın | E7: 1 | F7: Elf | G7: Kadın | H7: Fırtına | I7: Yaşam ve Ölüm Eşiği | J7: YASAM_TANRISI; IYILESTIRME_TANRISI; OLUM_TANRISI; Sonsuz_Savunma; Kanli_Kalkan; YASAM_EFENDISI; Kadim_Yasam_Efendisi; KADIM_SIFACI; Efsanevi_Iyilestirici; Sonsuz_Yasamin_Bekcisi | K7: Destek Ağı | L7: Nehrini kurtarmak için Ölüm Tanrısı'yla anlaştı. Suları herkese yaşam verir; yalnız içinden yükselen annesinin sesi hiç susmaz. | M7: =LEN(L7) -> 127 | N7: =IF(L7="","Eksik",IF(M7<=130,"Uygun","130 karakteri aşıyor")) -> Uygun | O7: 10 | P7: Yaşam akışı doğrudan tanrısal antlaşmaya bağlanıyor.
A8: 7 | B8: Kutsal_Isik | C8: Destek | D8: Yaygın | E8: 1 | F8: Melek | G8: Erkek | H8: Işık | I8: Kutsal Taht | J8: Kutsal_Asker; Kutsal_Zirh; Tacsiz_Muhafiz; KUTSAL_KILIC; ZAFER_MELEGI; GOKYUZU_HAKIMI; ISIK_USTASI; Savunma_Prensesi_Insan; KUTSAL_MUHAFIZ | K8: Destek Ağı | L8: Kutsal Taht'ın suçlu saydığı çocuğu iyileştirdiği için sürüldü. Kanatları söküldü ama ışığını kimin hak ettiğini kendisi seçer. | M8: =LEN(L8) -> 127 | N8: =IF(L8="","Eksik",IF(M8<=130,"Uygun","130 karakteri aşıyor")) -> Uygun | O8: 9 | P8: Işık, basit iyileştirme değil hüküm seçme aracı.
A9: 8 | B9: Sonsuz_Sifaci | C9: Destek | D9: Yaygın | E9: 1 | F9: Ölümsüz | G9: Kadın | H9: Ateş | I9: Yaşam ve Ölüm Eşiği | J9: YASAM_TANRISI; IYILESTIRME_TANRISI; OLUM_TANRISI; Sonsuz_Savunma; Kanli_Kalkan; YASAM_EFENDISI; Kadim_Yasam_Efendisi; KADIM_SIFACI; Efsanevi_Iyilestirici; Sonsuz_Yasamin_Bekcisi | K9: Destek Ağı | L9: Ölümsüzlüğünü bir köye adadı; köy yüzyıllar önce yok oldu. Şifa verdiği yüzlerde hâlâ ilk hastasının gülüşünü arar. | M9: =LEN(L9) -> 115 | N9: =IF(L9="","Eksik",IF(M9<=130,"Uygun","130 karakteri aşıyor")) -> Uygun | O9: 10 | P9: Şifa her zaman rahatlama değil; görev bedeli yaratıyor.
A10: 9 | B10: Isik_Yoldasi | C10: Destek | D10: Yaygın | E10: 1 | F10: İnsan | G10: Erkek | H10: Işık | I10: Gölge Antlaşması | J10: KARA_SOVALYE; Karanlik_Savasci; Golge_Kalkani; GOLGE_LORDU; GOLGELER_EFENDISI; GOLGE_BUYUCUSU; Zifiri_Buyucu; ABIS_GARDIYANI_golge; Kara_Pence; Kritik_Golge_Golge | K10: Destek Ağı | L10: Kara Şövalye'yi öldürmeye gitti, karanlıkta onunla sağ kaldı. Şimdi ışığı bir düşmanı değil, ikisinin de eve dönüş yolunu korur. | M10: =LEN(L10) -> 128 | N10: =IF(L10="","Eksik",IF(M10<=130,"Uygun","130 karakteri aşıyor")) -> Uygun | O10: 10 | P10: Işık-gölge geçişini kuran ara düğüm.
A11: 10 | B11: Doga_Efendisi | C11: Destek | D11: Yaygın | E11: 1 | F11: Elf | G11: Erkek | H11: Enerji | I11: Doğa ve Zirve Geçidi | J11: Zirve_Pencesi; Zirve_Kilici; Zirve_Efendisi; Kaya_Bekcisi_hayvan; Kum_Zirhli_Cuce; Gece_Yilani_Surungensoy; Vahsi_Elementalist; DOVUS_USTASI; Zirhli_Dev_Ejdersoy | K11: Destek Ağı | L11: Zirve Geçidi'ni köklerle mühürledi; ardında kendi halkı da kaldı. Ormanı koruyan her dal, bir gün yüzleşeceği o kararı hatırlatır. | M11: =LEN(L11) -> 130 | N11: =IF(L11="","Eksik",IF(M11<=130,"Uygun","130 karakteri aşıyor")) -> Uygun | O11: 9 | P11: Doğa, pasif ortam değil stratejik savunma alanı.
A12: 11 | B12: Zihinsel_Sifaci | C12: Destek | D12: Yaygın | E12: 1 | F12: İnsan | G12: Kadın | H12: Gölge | I12: Zihin ve Felsefe Mahkemesi | J12: Felsefe_Buyucusu; Yuce_Akil; Korku_Imparatoru_golge; Korgoz_Suikastci_Cuce; Buyuk_Tehlike; Karanlik_Kader; Kader_Orgusu_Arkan_buyucusu; SAVAS_TANRISI | K12: Destek Ağı | L12: Yüce Akıl'ın zihnini onardı, korkunç sırrını öğrendi. Hastasını koruma yeminiyle dünyayı uyarma isteği arasında anılarını siler. | M12: =LEN(L12) -> 128 | N12: =IF(L12="","Eksik",IF(M12<=130,"Uygun","130 karakteri aşıyor")) -> Uygun | O12: 8 | P12: Şifa edilen sır, başka bir karakterin silahına dönüşüyor.
